<?xml version="1.0" encoding="utf-8"?>
<robot
  name="harvest-studio" xmlns:xacro="http://ros.org/wiki/xacro">
  <link name="dummy">
  </link>
  <link
    name="stand_base">
    <inertial>
      <origin
        xyz="-0.00244095696499763 0.0834846502705878 0.0120971081555862"
        rpy="0 0 0" />
      <mass
        value="17.4192822915786" />
      <inertia
        ixx="0.365207090762505"
        ixy="1.51826662793011E-05"
        ixz="-4.58049242566518E-08"
        iyy="0.347003054917912"
        iyz="-5.19603726593645E-07"
        izz="0.177730015853551" />
    </inertial>
    <visual>
      <origin
        xyz="0 0 0"
        rpy="0 0 0" />
      <geometry>
        <mesh
          filename="file:///$(find harvest_studio_description)/stand_base.STL" />
      </geometry>
      <material
        name="">
        <color
          rgba="0.752941176470588 0.752941176470588 0.752941176470588 1" />
      </material>
    </visual>
    <collision>
      <origin
        xyz="0 0 0"
        rpy="0 0 0" />
      <geometry>
        <mesh
          filename="file:///$(find harvest_studio_description)/stand_base.STL" />
      </geometry>
    </collision>
  </link>
    <joint name="dummy_joint" type="fixed">
    <parent link="dummy"/>
    <child link="stand_base"/>
  </joint>
  <link
    name="azure_camera_link">
    <inertial>
      <origin
        xyz="-2.657383322537E-06 0.00348132910528381 0.0446566695341433"
        rpy="0 0 0" />
      <mass
        value="2.78889236681522" />
      <inertia
        ixx="0.00412183232658945"
        ixy="4.09236432683366E-07"
        ixz="-3.17078316364308E-08"
        iyy="0.00242404662476713"
        iyz="0.000234310769319999"
        izz="0.00609587810828995" />
    </inertial>
    <visual>
      <origin
        xyz="0 0 0"
        rpy="0 0 0" />
      <geometry>
        <mesh
          filename="file:///$(find harvest_studio_description)/azure_camera_link.STL" />
      </geometry>
      <material
        name="">
        <color
          rgba="0.792156862745098 0.819607843137255 0.933333333333333 1" />
      </material>
    </visual>
    <collision>
      <origin
        xyz="0 0 0"
        rpy="0 0 0" />
      <geometry>
        <mesh
          filename="file:///$(find harvest_studio_description)/azure_camera_link.STL" />
      </geometry>
    </collision>
  </link>
  <joint 
   name="azure_camera_joint" 
   type="revolute">
    <origin 
     xyz="0.00385 0.465 0.98" 
     rpy="0 0 -3.1416" />
    <parent 
     link="stand_base" />
    <child 
     link="azure_camera_link" />
    <axis xyz="1 0 0" />
    <limit 
     lower="-0.5" 
     upper="0.5"
      effort="0" 
      velocity="0" />
  </joint>
  <link
    name="right_arm_link">
    <inertial>
      <origin
        xyz="-0.0921692043278863 0.101109637912098 -0.00094798511080818"
        rpy="0 0 0" />
      <mass
        value="0.879635804902705" />
      <inertia
        ixx="0.00101359963830436"
        ixy="0.000345626145803582"
        ixz="1.59140398416402E-07"
        iyy="0.00110135479443889"
        iyz="7.17570599023293E-08"
        izz="0.000932982342715155" />
    </inertial>
    <visual>
      <origin
        xyz="0 0 0"
        rpy="0 0 0" />
      <geometry>
        <mesh
          filename="file:///$(find harvest_studio_description)/right_arm_link.STL" />
      </geometry>
      <material
        name="">
        <color
          rgba="0.792156862745098 0.819607843137255 0.933333333333333 1" />
      </material>
    </visual>
    <collision>
      <origin
        xyz="0 0 0"
        rpy="0 0 0" />
      <geometry>
        <mesh
          filename="file:///$(find harvest_studio_description)/right_arm_link.STL" />
      </geometry>
    </collision>
  </link>
  <joint
    name="right_arm_joint"
    type="revolute">
    <origin
      xyz="-0.30665 -0.4925 -0.155"
      rpy="3.1416 0 0.90153" />
    <parent
      link="stand_base" />
    <child
      link="right_arm_link" />
    <axis
      xyz="0 0 1" />
    <limit
      lower="-1"
      upper="1"
      effort="0"
      velocity="0" />
  </joint>
  <link
    name="left_arm_link">
    <inertial>
      <origin
        xyz="-0.13125187743035 0.0386239273471152 0.000950962918044584"
        rpy="0 0 0" />
      <mass
        value="0.879657265086363" />
      <inertia
        ixx="0.00073064298535606"
        ixy="0.000120666064530641"
        ixz="-9.10646468836211E-08"
        iyy="0.00138432044490653"
        iyz="-1.38587279405028E-07"
        izz="0.000932986858091463" />
    </inertial>
    <visual>
      <origin
        xyz="0 0 0"
        rpy="0 0 0" />
      <geometry>
        <mesh
          filename="file:///$(find harvest_studio_description)/left_arm_link.STL" />
      </geometry>
      <material
        name="">
        <color
          rgba="0.792156862745098 0.819607843137255 0.933333333333333 1" />
      </material>
    </visual>
    <collision>
      <origin
        xyz="0 0 0"
        rpy="0 0 0" />
      <geometry>
        <mesh
          filename="file:///$(find harvest_studio_description)/left_arm_link.STL" />
      </geometry>
    </collision>
  </link>
  <joint
    name="left_arm_joint"
    type="revolute">
    <origin
      xyz="0.30835 -0.505 -0.155"
      rpy="0 0 1.6946" />
    <parent
      link="stand_base" />
    <child
      link="left_arm_link" />
    <axis
      xyz="0 0 1" />
    <limit
      lower="-1"
      upper="1"
      effort="0"
      velocity="0" />
  </joint>
</robot>